[2021-08-31 13:26:25,228] {taskinstance.py:903} INFO - Dependencies all met for <TaskInstance: snowflake_test.get_count 2021-08-31T12:47:01.760509+00:00 [queued]>
[2021-08-31 13:26:25,281] {taskinstance.py:903} INFO - Dependencies all met for <TaskInstance: snowflake_test.get_count 2021-08-31T12:47:01.760509+00:00 [queued]>
[2021-08-31 13:26:25,297] {taskinstance.py:1094} INFO - 
--------------------------------------------------------------------------------
[2021-08-31 13:26:25,298] {taskinstance.py:1095} INFO - Starting attempt 1 of 1
[2021-08-31 13:26:25,298] {taskinstance.py:1096} INFO - 
--------------------------------------------------------------------------------
[2021-08-31 13:26:25,313] {taskinstance.py:1114} INFO - Executing <Task(PythonOperator): get_count> on 2021-08-31T12:47:01.760509+00:00
[2021-08-31 13:26:25,323] {standard_task_runner.py:52} INFO - Started process 633 to run task
[2021-08-31 13:26:25,329] {standard_task_runner.py:76} INFO - Running: ['***', 'tasks', 'run', 'snowflake_test', 'get_count', '2021-08-31T12:47:01.760509+00:00', '--job-id', '40', '--pool', 'default_pool', '--raw', '--subdir', 'DAGS_FOLDER/snowflake.py', '--cfg-path', '/tmp/tmpvnrnnl1y', '--error-file', '/tmp/tmpph81wqca']
[2021-08-31 13:26:25,363] {standard_task_runner.py:77} INFO - Job 40: Subtask get_count
[2021-08-31 13:26:25,496] {logging_mixin.py:109} INFO - Running <TaskInstance: snowflake_test.get_count 2021-08-31T12:47:01.760509+00:00 [running]> on host f134af24bd93
[2021-08-31 13:26:25,581] {taskinstance.py:1251} INFO - Exporting the following env vars:
AIRFLOW_CTX_DAG_OWNER=Airflow
AIRFLOW_CTX_DAG_ID=snowflake_test
AIRFLOW_CTX_TASK_ID=get_count
AIRFLOW_CTX_EXECUTION_DATE=2021-08-31T12:47:01.760509+00:00
AIRFLOW_CTX_DAG_RUN_ID=manual__2021-08-31T12:47:01.760509+00:00
[2021-08-31 13:26:25,610] {taskinstance.py:1462} ERROR - Task failed with exception
Traceback (most recent call last):
  File "/home/airflow/.local/lib/python3.8/site-packages/airflow/models/taskinstance.py", line 1164, in _run_raw_task
    self._prepare_and_execute_task_with_callbacks(context, task)
  File "/home/airflow/.local/lib/python3.8/site-packages/airflow/models/taskinstance.py", line 1282, in _prepare_and_execute_task_with_callbacks
    result = self._execute_task(context, task_copy)
  File "/home/airflow/.local/lib/python3.8/site-packages/airflow/models/taskinstance.py", line 1312, in _execute_task
    result = task_copy.execute(context=context)
  File "/home/airflow/.local/lib/python3.8/site-packages/airflow/operators/python.py", line 150, in execute
    return_value = self.execute_callable()
  File "/home/airflow/.local/lib/python3.8/site-packages/airflow/operators/python.py", line 161, in execute_callable
    return self.python_callable(*self.op_args, **self.op_kwargs)
  File "/opt/airflow/dags/snowflake.py", line 36, in get_row_count
    result = dwh_hook.get_first("select count(*) from public.test_table")
  File "/home/airflow/.local/lib/python3.8/site-packages/airflow/hooks/dbapi.py", line 147, in get_first
    with closing(self.get_conn()) as conn:
  File "/home/airflow/.local/lib/python3.8/site-packages/airflow/providers/snowflake/hooks/snowflake.py", line 222, in get_conn
    conn_config = self._get_conn_params()
  File "/home/airflow/.local/lib/python3.8/site-packages/airflow/providers/snowflake/hooks/snowflake.py", line 153, in _get_conn_params
    conn = self.get_connection(self.snowflake_conn_id)  # type: ignore[attr-defined]
  File "/home/airflow/.local/lib/python3.8/site-packages/airflow/hooks/base.py", line 68, in get_connection
    conn = Connection.get_connection_from_secrets(conn_id)
  File "/home/airflow/.local/lib/python3.8/site-packages/airflow/models/connection.py", line 379, in get_connection_from_secrets
    raise AirflowNotFoundException(f"The conn_id `{conn_id}` isn't defined")
airflow.exceptions.AirflowNotFoundException: The conn_id `snowflake_conn` isn't defined
[2021-08-31 13:26:25,650] {taskinstance.py:1505} INFO - Marking task as FAILED. dag_id=snowflake_test, task_id=get_count, execution_date=20210831T124701, start_date=20210831T132625, end_date=20210831T132625
[2021-08-31 13:26:25,716] {local_task_job.py:151} INFO - Task exited with return code 1
[2021-08-31 13:26:25,760] {local_task_job.py:261} INFO - 0 downstream tasks scheduled from follow-on schedule check
