[2021-08-31 12:47:04,209] {taskinstance.py:903} INFO - Dependencies all met for <TaskInstance: snowflake_test.snowfalke_create 2021-08-31T12:47:01.760509+00:00 [queued]>
[2021-08-31 12:47:04,228] {taskinstance.py:903} INFO - Dependencies all met for <TaskInstance: snowflake_test.snowfalke_create 2021-08-31T12:47:01.760509+00:00 [queued]>
[2021-08-31 12:47:04,228] {taskinstance.py:1094} INFO - 
--------------------------------------------------------------------------------
[2021-08-31 12:47:04,228] {taskinstance.py:1095} INFO - Starting attempt 1 of 1
[2021-08-31 12:47:04,229] {taskinstance.py:1096} INFO - 
--------------------------------------------------------------------------------
[2021-08-31 12:47:04,239] {taskinstance.py:1114} INFO - Executing <Task(SnowflakeOperator): snowfalke_create> on 2021-08-31T12:47:01.760509+00:00
[2021-08-31 12:47:04,245] {standard_task_runner.py:52} INFO - Started process 2515 to run task
[2021-08-31 12:47:04,250] {standard_task_runner.py:76} INFO - Running: ['***', 'tasks', 'run', 'snowflake_test', 'snowfalke_create', '2021-08-31T12:47:01.760509+00:00', '--job-id', '25', '--pool', 'default_pool', '--raw', '--subdir', 'DAGS_FOLDER/snowflake.py', '--cfg-path', '/tmp/tmp792toffi', '--error-file', '/tmp/tmp1cinc7rz']
[2021-08-31 12:47:04,252] {standard_task_runner.py:77} INFO - Job 25: Subtask snowfalke_create
[2021-08-31 12:47:04,298] {logging_mixin.py:109} INFO - Running <TaskInstance: snowflake_test.snowfalke_create 2021-08-31T12:47:01.760509+00:00 [running]> on host f134af24bd93
[2021-08-31 12:47:04,359] {taskinstance.py:1251} INFO - Exporting the following env vars:
AIRFLOW_CTX_DAG_OWNER=Airflow
AIRFLOW_CTX_DAG_ID=snowflake_test
AIRFLOW_CTX_TASK_ID=snowfalke_create
AIRFLOW_CTX_EXECUTION_DATE=2021-08-31T12:47:01.760509+00:00
AIRFLOW_CTX_DAG_RUN_ID=manual__2021-08-31T12:47:01.760509+00:00
[2021-08-31 12:47:04,360] {snowflake.py:121} INFO - Executing: ['create table public.test_employee (id number, name string);', 'insert into public.test_employee values(1, "Sam"),(2, "Andy"),(3, "Gill");']
[2021-08-31 12:47:04,380] {base.py:70} INFO - Using connection to: id: snowflake_default. Host: https://tm52136.west-us-2.azure.snowflakecomputing.com/, Port: None, Schema: RPY_SCH, Login: incspn, Password: ***, extra: {'extra__snowflake__account': '', 'extra__snowflake__aws_access_key_id': '', 'extra__snowflake__aws_secret_access_key': '***', 'extra__snowflake__database': 'RPY_DB', 'extra__snowflake__region': '', 'extra__snowflake__role': '', 'extra__snowflake__warehouse': ''}
[2021-08-31 12:47:04,382] {connection.py:270} INFO - Snowflake Connector for Python Version: 2.6.0, Python Version: 3.8.11, Platform: Linux-5.4.0-81-generic-x86_64-with-glibc2.2.5
[2021-08-31 12:47:04,391] {taskinstance.py:1462} ERROR - Task failed with exception
Traceback (most recent call last):
  File "/home/airflow/.local/lib/python3.8/site-packages/airflow/models/taskinstance.py", line 1164, in _run_raw_task
    self._prepare_and_execute_task_with_callbacks(context, task)
  File "/home/airflow/.local/lib/python3.8/site-packages/airflow/models/taskinstance.py", line 1282, in _prepare_and_execute_task_with_callbacks
    result = self._execute_task(context, task_copy)
  File "/home/airflow/.local/lib/python3.8/site-packages/airflow/models/taskinstance.py", line 1312, in _execute_task
    result = task_copy.execute(context=context)
  File "/home/airflow/.local/lib/python3.8/site-packages/airflow/providers/snowflake/operators/snowflake.py", line 123, in execute
    execution_info = hook.run(self.sql, autocommit=self.autocommit, parameters=self.parameters)
  File "/home/airflow/.local/lib/python3.8/site-packages/airflow/providers/snowflake/hooks/snowflake.py", line 271, in run
    with self.get_conn() as conn:
  File "/home/airflow/.local/lib/python3.8/site-packages/airflow/providers/snowflake/hooks/snowflake.py", line 223, in get_conn
    conn = connector.connect(**conn_config)
  File "/home/airflow/.local/lib/python3.8/site-packages/snowflake/connector/__init__.py", line 50, in Connect
    return SnowflakeConnection(**kwargs)
  File "/home/airflow/.local/lib/python3.8/site-packages/snowflake/connector/connection.py", line 286, in __init__
    self.connect(**kwargs)
  File "/home/airflow/.local/lib/python3.8/site-packages/snowflake/connector/connection.py", line 503, in connect
    self.__config(**kwargs)
  File "/home/airflow/.local/lib/python3.8/site-packages/snowflake/connector/connection.py", line 880, in __config
    Error.errorhandler_wrapper(
  File "/home/airflow/.local/lib/python3.8/site-packages/snowflake/connector/errors.py", line 254, in errorhandler_wrapper
    handed_over = Error.hand_to_other_handler(
  File "/home/airflow/.local/lib/python3.8/site-packages/snowflake/connector/errors.py", line 312, in hand_to_other_handler
    connection.errorhandler(connection, cursor, error_class, error_value)
  File "/home/airflow/.local/lib/python3.8/site-packages/snowflake/connector/errors.py", line 188, in default_errorhandler
    raise error_class(
snowflake.connector.errors.ProgrammingError: Account must be specified
[2021-08-31 12:47:04,392] {taskinstance.py:1505} INFO - Marking task as FAILED. dag_id=snowflake_test, task_id=snowfalke_create, execution_date=20210831T124701, start_date=20210831T124704, end_date=20210831T124704
[2021-08-31 12:47:04,459] {local_task_job.py:151} INFO - Task exited with return code 1
[2021-08-31 12:47:04,502] {local_task_job.py:261} INFO - 0 downstream tasks scheduled from follow-on schedule check
