[2021-08-31 12:51:25,281] {taskinstance.py:903} INFO - Dependencies all met for <TaskInstance: snowflake_test.snowfalke_create 2021-08-31T12:47:01.760509+00:00 [queued]>
[2021-08-31 12:51:25,300] {taskinstance.py:903} INFO - Dependencies all met for <TaskInstance: snowflake_test.snowfalke_create 2021-08-31T12:47:01.760509+00:00 [queued]>
[2021-08-31 12:51:25,300] {taskinstance.py:1094} INFO - 
--------------------------------------------------------------------------------
[2021-08-31 12:51:25,300] {taskinstance.py:1095} INFO - Starting attempt 3 of 3
[2021-08-31 12:51:25,300] {taskinstance.py:1096} INFO - 
--------------------------------------------------------------------------------
[2021-08-31 12:51:25,312] {taskinstance.py:1114} INFO - Executing <Task(SnowflakeOperator): snowfalke_create> on 2021-08-31T12:47:01.760509+00:00
[2021-08-31 12:51:25,319] {standard_task_runner.py:52} INFO - Started process 3113 to run task
[2021-08-31 12:51:25,324] {standard_task_runner.py:76} INFO - Running: ['***', 'tasks', 'run', 'snowflake_test', 'snowfalke_create', '2021-08-31T12:47:01.760509+00:00', '--job-id', '31', '--pool', 'default_pool', '--raw', '--subdir', 'DAGS_FOLDER/snowflake.py', '--cfg-path', '/tmp/tmp5og24wyw', '--error-file', '/tmp/tmpxl8catgl']
[2021-08-31 12:51:25,325] {standard_task_runner.py:77} INFO - Job 31: Subtask snowfalke_create
[2021-08-31 12:51:25,378] {logging_mixin.py:109} INFO - Running <TaskInstance: snowflake_test.snowfalke_create 2021-08-31T12:47:01.760509+00:00 [running]> on host f134af24bd93
[2021-08-31 12:51:25,447] {taskinstance.py:1251} INFO - Exporting the following env vars:
AIRFLOW_CTX_DAG_OWNER=Airflow
AIRFLOW_CTX_DAG_ID=snowflake_test
AIRFLOW_CTX_TASK_ID=snowfalke_create
AIRFLOW_CTX_EXECUTION_DATE=2021-08-31T12:47:01.760509+00:00
AIRFLOW_CTX_DAG_RUN_ID=manual__2021-08-31T12:47:01.760509+00:00
[2021-08-31 12:51:25,448] {snowflake.py:121} INFO - Executing: ['create table public.test_employee (id number, name string);', 'insert into public.test_employee values(1, "Sam"),(2, "Andy"),(3, "Gill");']
[2021-08-31 12:51:25,460] {base.py:70} INFO - Using connection to: id: snowflake_default. Host: https://tm52136.west-us-2.azure.snowflakecomputing.com/, Port: None, Schema: RPY_SCH, Login: incspn, Password: ***, extra: {'extra__snowflake__account': 'tm52136', 'extra__snowflake__aws_access_key_id': '', 'extra__snowflake__aws_secret_access_key': '***', 'extra__snowflake__database': 'RPY_DB', 'extra__snowflake__region': 'west-us-2', 'extra__snowflake__role': 'azure', 'extra__snowflake__warehouse': ''}
[2021-08-31 12:51:25,461] {connection.py:270} INFO - Snowflake Connector for Python Version: 2.6.0, Python Version: 3.8.11, Platform: Linux-5.4.0-81-generic-x86_64-with-glibc2.2.5
[2021-08-31 12:51:25,462] {connection.py:890} INFO - This connection is in OCSP Fail Open Mode. TLS Certificates would be checked for validity and revocation status. Any other Certificate Revocation related exceptions or OCSP Responder failures would be disregarded in favor of connectivity.
[2021-08-31 12:51:25,463] {connection.py:908} INFO - Setting use_openssl_only mode to False
[2021-08-31 12:51:26,219] {connection.py:514} WARNING - Certificate did not match expected hostname: tm52136.west-us-2.snowflakecomputing.com. Certificate: {'subject': ((('commonName', '*.us-west-2.snowflakecomputing.com'),),), 'subjectAltName': [('DNS', '*.us-west-2.snowflakecomputing.com'), ('DNS', '*.us-west-2.aws.snowflakecomputing.com'), ('DNS', '*.global.snowflakecomputing.com'), ('DNS', '*.snowflakecomputing.com'), ('DNS', '*.prod1.us-west-2.aws.snowflakecomputing.com'), ('DNS', '*.prod2.us-west-2.aws.snowflakecomputing.com')]}
[2021-08-31 12:51:26,220] {connectionpool.py:780} WARNING - Retrying (Retry(total=0, connect=None, read=None, redirect=None, status=None)) after connection broken by 'SSLError(SSLCertVerificationError("hostname 'tm52136.west-us-2.snowflakecomputing.com' doesn't match either of '*.us-west-2.snowflakecomputing.com', '*.us-west-2.aws.snowflakecomputing.com', '*.global.snowflakecomputing.com', '*.snowflakecomputing.com', '*.prod1.us-west-2.aws.snowflakecomputing.com', '*.prod2.us-west-2.aws.snowflakecomputing.com'"))': /session/v1/login-request?request_id=71c7b8f3-a99e-468d-b689-2b7e1b698225&databaseName=RPY_DB&schemaName=RPY_SCH&warehouse=&roleName=azure&request_guid=1098166e-f66c-4700-8eb0-c91f1110ecb0
[2021-08-31 12:51:26,395] {connection.py:514} WARNING - Certificate did not match expected hostname: tm52136.west-us-2.snowflakecomputing.com. Certificate: {'subject': ((('commonName', '*.us-west-2.snowflakecomputing.com'),),), 'subjectAltName': [('DNS', '*.us-west-2.snowflakecomputing.com'), ('DNS', '*.us-west-2.aws.snowflakecomputing.com'), ('DNS', '*.global.snowflakecomputing.com'), ('DNS', '*.snowflakecomputing.com'), ('DNS', '*.prod1.us-west-2.aws.snowflakecomputing.com'), ('DNS', '*.prod2.us-west-2.aws.snowflakecomputing.com')]}
[2021-08-31 12:51:26,399] {network.py:936} ERROR - Failed to get the response. Hanging? method: post, url: https://tm52136.west-us-2.snowflakecomputing.com:443/session/v1/login-request?request_id=71c7b8f3-a99e-468d-b689-2b7e1b698225&databaseName=RPY_DB&schemaName=RPY_SCH&warehouse=&roleName=azure&request_guid=1098166e-f66c-4700-8eb0-c91f1110ecb0, headers:{'Content-Type': 'application/json', 'accept': 'application/snowflake', 'User-Agent': 'PythonConnector/2.6.0 (Linux-5.4.0-81-generic-x86_64-with-glibc2.2.5) CPython/3.8.11', 'Content-Encoding': 'gzip'}, data: {"data": {"CLIENT_APP_ID": "PythonConnector", "CLIENT_APP_VERSION": "2.6.0", "SVN_REVISION": null, "ACCOUNT_NAME": "tm52136", "LOGIN_NAME": "incspn", "CLIENT_ENVIRONMENT": {"APPLICATION": "AIRFLOW", "OS": "Linux", "OS_VERSION": "Linux-5.4.0-81-generic-x86_64-with-glibc2.2.5", "PYTHON_VERSION": "3.8.11", "PYTHON_RUNTIME": "CPython", "PYTHON_COMPILER": "GCC 8.3.0", "OCSP_MODE": "FAIL_OPEN", "TRACING": 20, "LOGIN_TIMEOUT": 120, "NETWORK_TIMEOUT": null}, "PASSWORD": "********", "SESSION_PARAMETERS": {"CLIENT_PREFETCH_THREADS": 4}}}
[2021-08-31 12:51:26,404] {taskinstance.py:1462} ERROR - Task failed with exception
Traceback (most recent call last):
  File "/home/airflow/.local/lib/python3.8/site-packages/airflow/models/taskinstance.py", line 1164, in _run_raw_task
    self._prepare_and_execute_task_with_callbacks(context, task)
  File "/home/airflow/.local/lib/python3.8/site-packages/airflow/models/taskinstance.py", line 1282, in _prepare_and_execute_task_with_callbacks
    result = self._execute_task(context, task_copy)
  File "/home/airflow/.local/lib/python3.8/site-packages/airflow/models/taskinstance.py", line 1312, in _execute_task
    result = task_copy.execute(context=context)
  File "/home/airflow/.local/lib/python3.8/site-packages/airflow/providers/snowflake/operators/snowflake.py", line 123, in execute
    execution_info = hook.run(self.sql, autocommit=self.autocommit, parameters=self.parameters)
  File "/home/airflow/.local/lib/python3.8/site-packages/airflow/providers/snowflake/hooks/snowflake.py", line 271, in run
    with self.get_conn() as conn:
  File "/home/airflow/.local/lib/python3.8/site-packages/airflow/providers/snowflake/hooks/snowflake.py", line 223, in get_conn
    conn = connector.connect(**conn_config)
  File "/home/airflow/.local/lib/python3.8/site-packages/snowflake/connector/__init__.py", line 50, in Connect
    return SnowflakeConnection(**kwargs)
  File "/home/airflow/.local/lib/python3.8/site-packages/snowflake/connector/connection.py", line 286, in __init__
    self.connect(**kwargs)
  File "/home/airflow/.local/lib/python3.8/site-packages/snowflake/connector/connection.py", line 506, in connect
    self.__open_connection()
  File "/home/airflow/.local/lib/python3.8/site-packages/snowflake/connector/connection.py", line 745, in __open_connection
    self._authenticate(auth_instance)
  File "/home/airflow/.local/lib/python3.8/site-packages/snowflake/connector/connection.py", line 1006, in _authenticate
    self.__authenticate(self.__preprocess_auth_instance(auth_instance))
  File "/home/airflow/.local/lib/python3.8/site-packages/snowflake/connector/connection.py", line 1025, in __authenticate
    auth.authenticate(
  File "/home/airflow/.local/lib/python3.8/site-packages/snowflake/connector/auth.py", line 241, in authenticate
    ret = self._rest._post_request(
  File "/home/airflow/.local/lib/python3.8/site-packages/snowflake/connector/network.py", line 697, in _post_request
    ret = self.fetch(
  File "/home/airflow/.local/lib/python3.8/site-packages/snowflake/connector/network.py", line 787, in fetch
    ret = self._request_exec_wrapper(
  File "/home/airflow/.local/lib/python3.8/site-packages/snowflake/connector/network.py", line 909, in _request_exec_wrapper
    raise e
  File "/home/airflow/.local/lib/python3.8/site-packages/snowflake/connector/network.py", line 841, in _request_exec_wrapper
    self._handle_unknown_error(method, full_url, headers, data, conn)
  File "/home/airflow/.local/lib/python3.8/site-packages/snowflake/connector/network.py", line 941, in _handle_unknown_error
    Error.errorhandler_wrapper(
  File "/home/airflow/.local/lib/python3.8/site-packages/snowflake/connector/errors.py", line 254, in errorhandler_wrapper
    handed_over = Error.hand_to_other_handler(
  File "/home/airflow/.local/lib/python3.8/site-packages/snowflake/connector/errors.py", line 312, in hand_to_other_handler
    connection.errorhandler(connection, cursor, error_class, error_value)
  File "/home/airflow/.local/lib/python3.8/site-packages/snowflake/connector/errors.py", line 188, in default_errorhandler
    raise error_class(
snowflake.connector.errors.OperationalError: Failed to get the response. Hanging? method: post, url: https://tm52136.west-us-2.snowflakecomputing.com:443/session/v1/login-request?request_id=71c7b8f3-a99e-468d-b689-2b7e1b698225&databaseName=RPY_DB&schemaName=RPY_SCH&warehouse=&roleName=azure&request_guid=1098166e-f66c-4700-8eb0-c91f1110ecb0
[2021-08-31 12:51:26,405] {taskinstance.py:1505} INFO - Marking task as FAILED. dag_id=snowflake_test, task_id=snowfalke_create, execution_date=20210831T124701, start_date=20210831T125125, end_date=20210831T125126
[2021-08-31 12:51:26,457] {local_task_job.py:151} INFO - Task exited with return code 1
[2021-08-31 12:51:26,504] {local_task_job.py:261} INFO - 0 downstream tasks scheduled from follow-on schedule check
