[2021-08-31 13:18:42,412] {taskinstance.py:903} INFO - Dependencies all met for <TaskInstance: snowflake_test.snowfalke_create 2021-08-31T12:47:01.760509+00:00 [queued]>
[2021-08-31 13:18:42,432] {taskinstance.py:903} INFO - Dependencies all met for <TaskInstance: snowflake_test.snowfalke_create 2021-08-31T12:47:01.760509+00:00 [queued]>
[2021-08-31 13:18:42,432] {taskinstance.py:1094} INFO - 
--------------------------------------------------------------------------------
[2021-08-31 13:18:42,432] {taskinstance.py:1095} INFO - Starting attempt 6 of 6
[2021-08-31 13:18:42,432] {taskinstance.py:1096} INFO - 
--------------------------------------------------------------------------------
[2021-08-31 13:18:42,443] {taskinstance.py:1114} INFO - Executing <Task(SnowflakeOperator): snowfalke_create> on 2021-08-31T12:47:01.760509+00:00
[2021-08-31 13:18:42,449] {standard_task_runner.py:52} INFO - Started process 5248 to run task
[2021-08-31 13:18:42,455] {standard_task_runner.py:76} INFO - Running: ['***', 'tasks', 'run', 'snowflake_test', 'snowfalke_create', '2021-08-31T12:47:01.760509+00:00', '--job-id', '34', '--pool', 'default_pool', '--raw', '--subdir', 'DAGS_FOLDER/snowflake.py', '--cfg-path', '/tmp/tmpk5aibm5z', '--error-file', '/tmp/tmp5u3h3yzg']
[2021-08-31 13:18:42,456] {standard_task_runner.py:77} INFO - Job 34: Subtask snowfalke_create
[2021-08-31 13:18:42,510] {logging_mixin.py:109} INFO - Running <TaskInstance: snowflake_test.snowfalke_create 2021-08-31T12:47:01.760509+00:00 [running]> on host f134af24bd93
[2021-08-31 13:18:42,589] {taskinstance.py:1251} INFO - Exporting the following env vars:
AIRFLOW_CTX_DAG_OWNER=Airflow
AIRFLOW_CTX_DAG_ID=snowflake_test
AIRFLOW_CTX_TASK_ID=snowfalke_create
AIRFLOW_CTX_EXECUTION_DATE=2021-08-31T12:47:01.760509+00:00
AIRFLOW_CTX_DAG_RUN_ID=manual__2021-08-31T12:47:01.760509+00:00
[2021-08-31 13:18:42,591] {snowflake.py:121} INFO - Executing: <function today_in_california at 0x7fc5e69e0d30>
[2021-08-31 13:18:42,606] {base.py:70} INFO - Using connection to: id: snowflake_default. Host: https://tm52136.west-us-2.azure.snowflakecomputing.com/, Port: None, Schema: RPY_SCH, Login: incspn, Password: ***, extra: {'extra__snowflake__account': 'tm52136', 'extra__snowflake__aws_access_key_id': '', 'extra__snowflake__aws_secret_access_key': '***', 'extra__snowflake__database': 'RPY_DB', 'extra__snowflake__region': 'west-us-2.azure', 'extra__snowflake__role': '', 'extra__snowflake__warehouse': ''}
[2021-08-31 13:18:42,607] {connection.py:270} INFO - Snowflake Connector for Python Version: 2.6.0, Python Version: 3.8.11, Platform: Linux-5.4.0-81-generic-x86_64-with-glibc2.2.5
[2021-08-31 13:18:42,608] {connection.py:890} INFO - This connection is in OCSP Fail Open Mode. TLS Certificates would be checked for validity and revocation status. Any other Certificate Revocation related exceptions or OCSP Responder failures would be disregarded in favor of connectivity.
[2021-08-31 13:18:42,608] {connection.py:908} INFO - Setting use_openssl_only mode to False
[2021-08-31 13:18:44,087] {base.py:70} INFO - Using connection to: id: snowflake_default. Host: https://tm52136.west-us-2.azure.snowflakecomputing.com/, Port: None, Schema: RPY_SCH, Login: incspn, Password: ***, extra: {'extra__snowflake__account': 'tm52136', 'extra__snowflake__aws_access_key_id': '', 'extra__snowflake__aws_secret_access_key': '***', 'extra__snowflake__database': 'RPY_DB', 'extra__snowflake__region': 'west-us-2.azure', 'extra__snowflake__role': '', 'extra__snowflake__warehouse': ''}
[2021-08-31 13:18:44,088] {connection.py:270} INFO - Snowflake Connector for Python Version: 2.6.0, Python Version: 3.8.11, Platform: Linux-5.4.0-81-generic-x86_64-with-glibc2.2.5
[2021-08-31 13:18:44,089] {connection.py:890} INFO - This connection is in OCSP Fail Open Mode. TLS Certificates would be checked for validity and revocation status. Any other Certificate Revocation related exceptions or OCSP Responder failures would be disregarded in favor of connectivity.
[2021-08-31 13:18:44,881] {cursor.py:678} INFO - query: [ALTER SESSION SET autocommit=True]
[2021-08-31 13:18:45,011] {cursor.py:702} INFO - query execution done
[2021-08-31 13:18:45,012] {connection.py:521} INFO - closed
[2021-08-31 13:18:45,012] {connection.py:524} INFO - No async queries seem to be running, deleting session
[2021-08-31 13:18:45,124] {taskinstance.py:1462} ERROR - Task failed with exception
Traceback (most recent call last):
  File "/home/airflow/.local/lib/python3.8/site-packages/airflow/models/taskinstance.py", line 1164, in _run_raw_task
    self._prepare_and_execute_task_with_callbacks(context, task)
  File "/home/airflow/.local/lib/python3.8/site-packages/airflow/models/taskinstance.py", line 1282, in _prepare_and_execute_task_with_callbacks
    result = self._execute_task(context, task_copy)
  File "/home/airflow/.local/lib/python3.8/site-packages/airflow/models/taskinstance.py", line 1312, in _execute_task
    result = task_copy.execute(context=context)
  File "/home/airflow/.local/lib/python3.8/site-packages/airflow/providers/snowflake/operators/snowflake.py", line 123, in execute
    execution_info = hook.run(self.sql, autocommit=self.autocommit, parameters=self.parameters)
  File "/home/airflow/.local/lib/python3.8/site-packages/airflow/providers/snowflake/hooks/snowflake.py", line 279, in run
    self.log.debug("Executing %d statements against Snowflake DB", len(sql))
TypeError: object of type 'function' has no len()
[2021-08-31 13:18:45,127] {taskinstance.py:1505} INFO - Marking task as FAILED. dag_id=snowflake_test, task_id=snowfalke_create, execution_date=20210831T124701, start_date=20210831T131842, end_date=20210831T131845
[2021-08-31 13:18:45,193] {local_task_job.py:151} INFO - Task exited with return code 1
[2021-08-31 13:18:45,238] {local_task_job.py:261} INFO - 0 downstream tasks scheduled from follow-on schedule check
