[2021-08-31 12:40:58,769] {taskinstance.py:903} INFO - Dependencies all met for <TaskInstance: snowflake_test.snowfalke_create 2021-08-31T12:40:03.928519+00:00 [queued]>
[2021-08-31 12:40:58,788] {taskinstance.py:903} INFO - Dependencies all met for <TaskInstance: snowflake_test.snowfalke_create 2021-08-31T12:40:03.928519+00:00 [queued]>
[2021-08-31 12:40:58,789] {taskinstance.py:1094} INFO - 
--------------------------------------------------------------------------------
[2021-08-31 12:40:58,789] {taskinstance.py:1095} INFO - Starting attempt 1 of 1
[2021-08-31 12:40:58,789] {taskinstance.py:1096} INFO - 
--------------------------------------------------------------------------------
[2021-08-31 12:40:58,801] {taskinstance.py:1114} INFO - Executing <Task(SnowflakeOperator): snowfalke_create> on 2021-08-31T12:40:03.928519+00:00
[2021-08-31 12:40:58,807] {standard_task_runner.py:52} INFO - Started process 1947 to run task
[2021-08-31 12:40:58,812] {standard_task_runner.py:76} INFO - Running: ['***', 'tasks', 'run', 'snowflake_test', 'snowfalke_create', '2021-08-31T12:40:03.928519+00:00', '--job-id', '22', '--pool', 'default_pool', '--raw', '--subdir', 'DAGS_FOLDER/snowflake.py', '--cfg-path', '/tmp/tmp0pnh_rdw', '--error-file', '/tmp/tmpgdvsp3lm']
[2021-08-31 12:40:58,813] {standard_task_runner.py:77} INFO - Job 22: Subtask snowfalke_create
[2021-08-31 12:40:58,865] {logging_mixin.py:109} INFO - Running <TaskInstance: snowflake_test.snowfalke_create 2021-08-31T12:40:03.928519+00:00 [running]> on host f134af24bd93
[2021-08-31 12:40:58,931] {taskinstance.py:1251} INFO - Exporting the following env vars:
AIRFLOW_CTX_DAG_OWNER=Airflow
AIRFLOW_CTX_DAG_ID=snowflake_test
AIRFLOW_CTX_TASK_ID=snowfalke_create
AIRFLOW_CTX_EXECUTION_DATE=2021-08-31T12:40:03.928519+00:00
AIRFLOW_CTX_DAG_RUN_ID=manual__2021-08-31T12:40:03.928519+00:00
[2021-08-31 12:40:58,932] {snowflake.py:121} INFO - Executing: ['create table public.test_employee (id number, name string);', 'insert into public.test_employee values(1, “Sam”),(2, “Andy”),(3, “Gill”);']
[2021-08-31 12:40:58,953] {taskinstance.py:1462} ERROR - Task failed with exception
Traceback (most recent call last):
  File "/home/airflow/.local/lib/python3.8/site-packages/airflow/models/taskinstance.py", line 1164, in _run_raw_task
    self._prepare_and_execute_task_with_callbacks(context, task)
  File "/home/airflow/.local/lib/python3.8/site-packages/airflow/models/taskinstance.py", line 1282, in _prepare_and_execute_task_with_callbacks
    result = self._execute_task(context, task_copy)
  File "/home/airflow/.local/lib/python3.8/site-packages/airflow/models/taskinstance.py", line 1312, in _execute_task
    result = task_copy.execute(context=context)
  File "/home/airflow/.local/lib/python3.8/site-packages/airflow/providers/snowflake/operators/snowflake.py", line 123, in execute
    execution_info = hook.run(self.sql, autocommit=self.autocommit, parameters=self.parameters)
  File "/home/airflow/.local/lib/python3.8/site-packages/airflow/providers/snowflake/hooks/snowflake.py", line 271, in run
    with self.get_conn() as conn:
  File "/home/airflow/.local/lib/python3.8/site-packages/airflow/providers/snowflake/hooks/snowflake.py", line 222, in get_conn
    conn_config = self._get_conn_params()
  File "/home/airflow/.local/lib/python3.8/site-packages/airflow/providers/snowflake/hooks/snowflake.py", line 153, in _get_conn_params
    conn = self.get_connection(self.snowflake_conn_id)  # type: ignore[attr-defined]
  File "/home/airflow/.local/lib/python3.8/site-packages/airflow/hooks/base.py", line 68, in get_connection
    conn = Connection.get_connection_from_secrets(conn_id)
  File "/home/airflow/.local/lib/python3.8/site-packages/airflow/models/connection.py", line 379, in get_connection_from_secrets
    raise AirflowNotFoundException(f"The conn_id `{conn_id}` isn't defined")
airflow.exceptions.AirflowNotFoundException: The conn_id `snowflake_conn` isn't defined
[2021-08-31 12:40:58,956] {taskinstance.py:1505} INFO - Marking task as FAILED. dag_id=snowflake_test, task_id=snowfalke_create, execution_date=20210831T124003, start_date=20210831T124058, end_date=20210831T124058
[2021-08-31 12:40:59,022] {local_task_job.py:151} INFO - Task exited with return code 1
[2021-08-31 12:40:59,061] {local_task_job.py:261} INFO - 0 downstream tasks scheduled from follow-on schedule check
