[2021-08-31 12:48:37,049] {taskinstance.py:903} INFO - Dependencies all met for <TaskInstance: snowflake_test.snowfalke_create 2021-08-31T12:43:50.478033+00:00 [queued]>
[2021-08-31 12:48:37,076] {taskinstance.py:903} INFO - Dependencies all met for <TaskInstance: snowflake_test.snowfalke_create 2021-08-31T12:43:50.478033+00:00 [queued]>
[2021-08-31 12:48:37,077] {taskinstance.py:1094} INFO - 
--------------------------------------------------------------------------------
[2021-08-31 12:48:37,077] {taskinstance.py:1095} INFO - Starting attempt 2 of 2
[2021-08-31 12:48:37,077] {taskinstance.py:1096} INFO - 
--------------------------------------------------------------------------------
[2021-08-31 12:48:37,089] {taskinstance.py:1114} INFO - Executing <Task(SnowflakeOperator): snowfalke_create> on 2021-08-31T12:43:50.478033+00:00
[2021-08-31 12:48:37,096] {standard_task_runner.py:52} INFO - Started process 2806 to run task
[2021-08-31 12:48:37,100] {standard_task_runner.py:76} INFO - Running: ['***', 'tasks', 'run', 'snowflake_test', 'snowfalke_create', '2021-08-31T12:43:50.478033+00:00', '--job-id', '29', '--pool', 'default_pool', '--raw', '--subdir', 'DAGS_FOLDER/snowflake.py', '--cfg-path', '/tmp/tmpbres46ck', '--error-file', '/tmp/tmpqmvv7vux']
[2021-08-31 12:48:37,101] {standard_task_runner.py:77} INFO - Job 29: Subtask snowfalke_create
[2021-08-31 12:48:37,156] {logging_mixin.py:109} INFO - Running <TaskInstance: snowflake_test.snowfalke_create 2021-08-31T12:43:50.478033+00:00 [running]> on host f134af24bd93
[2021-08-31 12:48:37,234] {taskinstance.py:1251} INFO - Exporting the following env vars:
AIRFLOW_CTX_DAG_OWNER=Airflow
AIRFLOW_CTX_DAG_ID=snowflake_test
AIRFLOW_CTX_TASK_ID=snowfalke_create
AIRFLOW_CTX_EXECUTION_DATE=2021-08-31T12:43:50.478033+00:00
AIRFLOW_CTX_DAG_RUN_ID=manual__2021-08-31T12:43:50.478033+00:00
[2021-08-31 12:48:37,234] {snowflake.py:121} INFO - Executing: ['create table public.test_employee (id number, name string);', 'insert into public.test_employee values(1, "Sam"),(2, "Andy"),(3, "Gill");']
[2021-08-31 12:48:37,249] {base.py:70} INFO - Using connection to: id: snowflake_default. Host: https://tm52136.west-us-2.azure.snowflakecomputing.com/, Port: None, Schema: RPY_SCH, Login: incspn, Password: ***, extra: {'extra__snowflake__account': 'tm52136', 'extra__snowflake__aws_access_key_id': '', 'extra__snowflake__aws_secret_access_key': '***', 'extra__snowflake__database': 'RPY_DB', 'extra__snowflake__region': '', 'extra__snowflake__role': '', 'extra__snowflake__warehouse': ''}
[2021-08-31 12:48:37,251] {connection.py:270} INFO - Snowflake Connector for Python Version: 2.6.0, Python Version: 3.8.11, Platform: Linux-5.4.0-81-generic-x86_64-with-glibc2.2.5
[2021-08-31 12:48:37,252] {connection.py:890} INFO - This connection is in OCSP Fail Open Mode. TLS Certificates would be checked for validity and revocation status. Any other Certificate Revocation related exceptions or OCSP Responder failures would be disregarded in favor of connectivity.
[2021-08-31 12:48:37,252] {connection.py:908} INFO - Setting use_openssl_only mode to False
[2021-08-31 12:50:42,141] {network.py:874} ERROR - HTTP 403: Forbidden
Traceback (most recent call last):
  File "/home/airflow/.local/lib/python3.8/site-packages/snowflake/connector/network.py", line 830, in _request_exec_wrapper
    return_object = self._request_exec(
  File "/home/airflow/.local/lib/python3.8/site-packages/snowflake/connector/network.py", line 1073, in _request_exec
    raise err
  File "/home/airflow/.local/lib/python3.8/site-packages/snowflake/connector/network.py", line 1014, in _request_exec
    raise RetryRequest(error)
snowflake.connector.network.RetryRequest: HTTP 403: Forbidden
[2021-08-31 12:50:42,533] {taskinstance.py:1462} ERROR - Task failed with exception
Traceback (most recent call last):
  File "/home/airflow/.local/lib/python3.8/site-packages/snowflake/connector/network.py", line 830, in _request_exec_wrapper
    return_object = self._request_exec(
  File "/home/airflow/.local/lib/python3.8/site-packages/snowflake/connector/network.py", line 1073, in _request_exec
    raise err
  File "/home/airflow/.local/lib/python3.8/site-packages/snowflake/connector/network.py", line 1014, in _request_exec
    raise RetryRequest(error)
snowflake.connector.network.RetryRequest: HTTP 403: Forbidden

During handling of the above exception, another exception occurred:

Traceback (most recent call last):
  File "/home/airflow/.local/lib/python3.8/site-packages/snowflake/connector/auth.py", line 241, in authenticate
    ret = self._rest._post_request(
  File "/home/airflow/.local/lib/python3.8/site-packages/snowflake/connector/network.py", line 697, in _post_request
    ret = self.fetch(
  File "/home/airflow/.local/lib/python3.8/site-packages/snowflake/connector/network.py", line 787, in fetch
    ret = self._request_exec_wrapper(
  File "/home/airflow/.local/lib/python3.8/site-packages/snowflake/connector/network.py", line 887, in _request_exec_wrapper
    Error.errorhandler_wrapper_from_cause(conn, cause)
  File "/home/airflow/.local/lib/python3.8/site-packages/snowflake/connector/errors.py", line 219, in errorhandler_wrapper_from_cause
    return Error.errorhandler_wrapper(
  File "/home/airflow/.local/lib/python3.8/site-packages/snowflake/connector/errors.py", line 254, in errorhandler_wrapper
    handed_over = Error.hand_to_other_handler(
  File "/home/airflow/.local/lib/python3.8/site-packages/snowflake/connector/errors.py", line 312, in hand_to_other_handler
    connection.errorhandler(connection, cursor, error_class, error_value)
  File "/home/airflow/.local/lib/python3.8/site-packages/snowflake/connector/errors.py", line 188, in default_errorhandler
    raise error_class(
snowflake.connector.errors.ForbiddenError: HTTP 403: Forbidden

During handling of the above exception, another exception occurred:

Traceback (most recent call last):
  File "/home/airflow/.local/lib/python3.8/site-packages/airflow/models/taskinstance.py", line 1164, in _run_raw_task
    self._prepare_and_execute_task_with_callbacks(context, task)
  File "/home/airflow/.local/lib/python3.8/site-packages/airflow/models/taskinstance.py", line 1282, in _prepare_and_execute_task_with_callbacks
    result = self._execute_task(context, task_copy)
  File "/home/airflow/.local/lib/python3.8/site-packages/airflow/models/taskinstance.py", line 1312, in _execute_task
    result = task_copy.execute(context=context)
  File "/home/airflow/.local/lib/python3.8/site-packages/airflow/providers/snowflake/operators/snowflake.py", line 123, in execute
    execution_info = hook.run(self.sql, autocommit=self.autocommit, parameters=self.parameters)
  File "/home/airflow/.local/lib/python3.8/site-packages/airflow/providers/snowflake/hooks/snowflake.py", line 271, in run
    with self.get_conn() as conn:
  File "/home/airflow/.local/lib/python3.8/site-packages/airflow/providers/snowflake/hooks/snowflake.py", line 223, in get_conn
    conn = connector.connect(**conn_config)
  File "/home/airflow/.local/lib/python3.8/site-packages/snowflake/connector/__init__.py", line 50, in Connect
    return SnowflakeConnection(**kwargs)
  File "/home/airflow/.local/lib/python3.8/site-packages/snowflake/connector/connection.py", line 286, in __init__
    self.connect(**kwargs)
  File "/home/airflow/.local/lib/python3.8/site-packages/snowflake/connector/connection.py", line 506, in connect
    self.__open_connection()
  File "/home/airflow/.local/lib/python3.8/site-packages/snowflake/connector/connection.py", line 745, in __open_connection
    self._authenticate(auth_instance)
  File "/home/airflow/.local/lib/python3.8/site-packages/snowflake/connector/connection.py", line 1006, in _authenticate
    self.__authenticate(self.__preprocess_auth_instance(auth_instance))
  File "/home/airflow/.local/lib/python3.8/site-packages/snowflake/connector/connection.py", line 1025, in __authenticate
    auth.authenticate(
  File "/home/airflow/.local/lib/python3.8/site-packages/snowflake/connector/auth.py", line 250, in authenticate
    raise err.__class__(
snowflake.connector.errors.ForbiddenError: 250001 (08001): None: Failed to connect to DB. Verify the account name is correct: tm52136.snowflakecomputing.com:443. HTTP 403: Forbidden
[2021-08-31 12:50:42,535] {taskinstance.py:1505} INFO - Marking task as FAILED. dag_id=snowflake_test, task_id=snowfalke_create, execution_date=20210831T124350, start_date=20210831T124837, end_date=20210831T125042
[2021-08-31 12:50:42,588] {local_task_job.py:151} INFO - Task exited with return code 1
[2021-08-31 12:50:42,633] {local_task_job.py:261} INFO - 0 downstream tasks scheduled from follow-on schedule check
